<mujoco model="panda_hand">
    <asset>
        <mesh name="hand" file="meshes/panda_gripper/hand.stl" />
        <mesh name="hand_vis" file="meshes/panda_gripper/hand_vis.stl" />
        <mesh name="finger" file="meshes/panda_gripper/finger.stl" />
        <mesh name="finger_vis" file="meshes/panda_gripper/finger_vis.stl" />
        <mesh name="finger_vis2" file="meshes/panda_gripper/finger_longer.stl" />
    </asset>
    <actuator>
        <position ctrllimited="true" ctrlrange="0.0 0.04" joint="finger_joint1" kp="1000" name="gripper_finger_joint1" forcelimited="true" forcerange="-20 20" />
        <position ctrllimited="true" ctrlrange="-0.04 0.0" joint="finger_joint2" kp="1000" name="gripper_finger_joint2" forcelimited="true" forcerange="-20 20" />
    </actuator>
    <worldbody>
        <body name="right_gripper" pos="0 0 0" quat="0.707107 0 0 -0.707107">
            <site name="ft_frame" pos="0 0 0" size="0.01 0.01 0.01" rgba="1 0 0 1" type="sphere" group="4" />
            <inertial pos="0 0 0.17" quat="0.707107 0.707107 0 0" mass="0.3" diaginertia="0.09 0.07 0.05" />
            <geom pos="0 0 0." quat="0.707107 0 0 0.707107" type="mesh" contype="0" conaffinity="0" group="4" mesh="hand_vis" name="hand_visual" rgba="1 1 1 1" />
            <geom pos="0 0 0." quat="0.707107 0 0 0.707107" type="mesh" mesh="hand" group="4" name="hand_collision" />
            
            <body name="eef" pos="0 0 0.097" quat="1 0 0 0">
                <site name="ee" pos="0 0 0" size="0.01 0.01 0.01" rgba="0 0 1 0.5" type="sphere" group="4" />
                <site name="grip_site" pos="0 0 0" size="0.01 0.01 0.01" rgba="1 0 0 0.5" type="sphere" group="4" />
                <site name="ee_x" pos="0.1 0 0" size="0.005 .1" quat="0.707105  0 0.707108 0 " rgba="1 0 0 0" type="cylinder" group="4" />
                <site name="ee_y" pos="0 0.1 0" size="0.005 .1" quat="0.707105 0.707108 0 0" rgba="0 1 0 0" type="cylinder" group="4" />
                <site name="ee_z" pos="0 0 0.1" size="0.005 .1" quat="1 0 0 0" rgba="0 0 1 0" type="cylinder" group="4" />
                
                <site name="grip_site_cylinder" pos="0 0 0" size="0.005 10" rgba="0 1 0 0.3" type="cylinder" group="4" />
            </body>
            <body name="leftfinger" pos="0 0 0.0524" quat="0.707107 0 0 0.707107">
                <inertial pos="0 0 0.05" mass="0.1" diaginertia="0.01 0.01 0.005" />
                <joint name="finger_joint1" pos="0 0 0" axis="0 1 0" type="slide" limited="true" range="0.0 0.04" damping="100" armature="1.0" frictionloss="1.0" />
                <geom type="mesh" contype="0" conaffinity="0" group="4" mesh="finger_vis" name="finger1_visual" rgba="0.499 0.499 0.499 1" />
                <geom type="mesh" group="4" conaffinity="1" contype="0" solref="0.02 1" friction="1 0.005 0.0001" condim="4" mesh="finger" name="finger1_collision" />
                <body name="finger_joint1_tip" pos="0 0.0085 0.056">
                    <inertial pos="0 0 0" quat="0 0 0 1" mass="0.01" diaginertia="0.01 0.01 0.01" />
                    <geom size="0.008 0.004 0.008" pos="0 0 -0.015" quat="0 0 0 1" type="box" group="4" solref="0.02 1" friction="2 0.05 0.0001" conaffinity="1" contype="1" name="finger1_pad_collision" rgba="0 0.5 1 0.7" solimp="0.9 0.95 0.001 0.5 2" />
                <camera name="tactile_cam_left" pos="0 0.0225 -0.015" euler="-90 0 0" fovy="60" /></body>
            </body>
            <body name="rightfinger" pos="0 0 0.0524" quat="0.707107 0 0 0.707107">
                <inertial pos="0 0 0.05" mass="0.1" diaginertia="0.01 0.01 0.005" />
                <joint name="finger_joint2" pos="0 0 0" axis="0 1 0" type="slide" limited="true" range="-0.04 0.0" damping="100" armature="1.0" frictionloss="1.0" />
                <geom quat="0 0 0 1" type="mesh" contype="0" conaffinity="0" group="4" mesh="finger_vis" name="finger2_visual" rgba="0.499 0.499 0.499 1" />
                <geom quat="0 0 0 1" type="mesh" group="4" conaffinity="1" contype="0" solref="0.02 1" friction="1 0.005 0.0001" condim="4" mesh="finger" name="finger2_collision" />
                <body name="finger_joint2_tip" pos="0 -0.0085 0.056">
                    <inertial pos="0 0 0" quat="0 0 0 1" mass="0.01" diaginertia="0.01 0.01 0.01" />
                    <geom size="0.008 0.004 0.008" pos="0 0 -0.015" quat="0 0 0 1" type="box" group="4" solref="0.02 1" friction="2 0.05 0.0001" conaffinity="1" contype="1" name="finger2_pad_collision" rgba="0 0.5 1 0.7" solimp="0.9 0.95 0.001 0.5 2" />
                <camera name="tactile_cam_right" pos="0 -0.0225 -0.015" euler="90 0 0" fovy="60" /></body>
            </body>
        </body>
    </worldbody>
    <sensor>
        <force name="force_ee" site="ft_frame" />
        <torque name="torque_ee" site="ft_frame" />
    </sensor>
</mujoco>